Workbook
Name AdhesiveList: #REF!
Name amount: #REF!
Name BagTypeList: #REF!
Name Barier: #REF!
Name Clear: #REF!
Name Config_302FG: #REF!
Name Config_302FGW: #REF!
Name Config_306: #REF!
Name Config_308: #REF!
Name Config_312FG: #REF!
Name Config_312W: #REF!
Name Config_NKR: #REF!
Name Config_PL2021: "'Film Pricing- New'!$AF$10:$AF$20"
Name Config_PL2022: "'Film Pricing- New'!$AG$10:$AG$20"
Name Config_PL2023: "'Film Pricing- New'!$AH$10:$AH$20"
Name Family: #REF!
Name Film_type: '[1]List of names'!$Y$15:$Y$16
Name Film_type: #REF!
Name FilmList: #REF!
Name GF048.1: #REF!
Name Grouped: #REF!
Name HardenerList: #REF!
Name JOB: OFFSET('[2]GEF063 WP Sales'!B6,0,0,COUNTA('[2]GEF063 WP Sales'!$AS$11:$AS$200),COUNTA('[2]GEF063 WP Sales'!$AS$11:$AT$11))
Name JOB: OFFSET(#REF!,0,0,COUNTA(#REF!),COUNTA(#REF!))
Name Jobs: '[2]GEF063 WP Sales'!$AS$10:$AS$210+'[2]GEF063 WP Sales'!$AU$10-2
Name Jobs: #REF!+#REF!-2
Name Jobss: '[2]GEF063 WP Sales'!XFC2:XFC2+VALUE('[2]GEF063 WP Sales'!$AU$10)
Name Jobss: #REF!+VALUE(#REF!)
Name Laminate: '[1]List of names'!$P$15:$P$22
Name Laminate: #REF!
Name Laminate_Thickness: #REF!
Name Laminate_type: '[1]List of names'!$P$14:$X$14
Name Laminate_type: #REF!
Name Laminate106: [3]!Table2[Laminate106]
Name Laminate106: [3]!Table2[Laminate106]
Name Laminate106: #REF!
Name Laminate604: [3]!Table4[Laminate618]
Name Laminate604: [1]!Table4[Laminate618]
Name Laminate604: [3]!Table4[Laminate618]
Name Laminate604: #REF!
Name Laminate607: [3]!Table6[Laminate607]
Name Laminate607: [3]!Table6[Laminate607]
Name Laminate607: #REF!
Name Laminate607\: [3]!Table6[Laminate607]
Name Laminate607\: [1]!Table6[Laminate607]
Name Laminate607\: [3]!Table6[Laminate607]
Name Laminate607\: #REF!
Name Laminate608W: [3]!Table3[Laminate608W]
Name Laminate608W: [1]!Table3[Laminate608W]
Name Laminate608W: [3]!Table3[Laminate608W]
Name Laminate608W: #REF!
Name LaminateList: #REF!
Name MATERIAL: '[4]Raw materials prices'!$L$51:$L$61
Name MATERIAL: #REF!
Name Materials: '[5]list for drop down menu'!$A$1:$A$20
Name Materials: #REF!
Name Metalize: #REF!
Name NKR: #REF!
Name Paper: #REF!
Name pirce: #REF!

Sheet Sheet1
A3: Film | B3: Grade | C3: Sum of Price Calculated(€) Thickness & QTY related
A4: TIPA 302FG | B4: S723 | C4: 0.2424
B5: S724 | C5: 0.02352
A6: TIPA 302FG W | B6: S723 | C6: 0.2424
B7: S724 | C7: 0.09408
A8: TIPA 306M | B8: S723 | C8: 0.2424
B9: S724 | C9: 0.0588
A10: TIPA 306W | B10: S723 | C10: 0.2424
B11: S724 | C11: 0.1176
A12: TIPA 312 MFG | B12: S723 | C12: 0.2424
B13: S724 | C13: 0.06762
A14: TIPA 312MFGW | B14: S723 | C14: 0.2424
B15: S724 | C15: 0.06762
A16: Grand Total | C16: 1.88364
A20: Film | B20: Price (€/kg) | C20: Price ($/kg)
A21: PL202.1 | B21: 8.995784 | C21: 10.435109
A22: PL202.2 | B22: 6.73178 | C22: 7.8088648
A23: PL202.3 | B23: 5.74578 | C23: 6.6651048
A24: TIPA 302FG | B24: 3.599712 | C24: 4.1756659
A25: TIPA 302FG W | B25: 3.916872 | C25: 4.5435715
A26: TIPA 306M | B26: 3.520798 | C26: 4.0841257
A27: TIPA 306W | B27: 3.805774 | C27: 4.4146978
A28: TIPA 312 MFG | B28: 2.899978 | C28: 3.3639745
A29: TIPA 312MFGW | B29: 3.178978 | C29: 3.6876145
A32: FILM | B32: Material | C32: % from Total
A33: TIPA 302FG | B33: S723 | C33: =C4/$B$24 -> 0.06733872
B34: S724 | C34: =C5/$B$24 -> 0.006533856
A35: TIPA 302FG W | B35: S723 | C35: =C6/$B$25 -> 0.061886117
B36: S724 | C36: =C7/$B$25 -> 0.024019166
A37: TIPA 306M | B37: S723 | C37: =C8/$B$26 -> 0.068848028
B38: S724 | C38: =C9/$B$26 -> 0.016700759
A39: TIPA 306W | B39: S723 | C39: =C10/$B$27 -> 0.063692694
B40: S724 | C40: =C11/$B$27 -> 0.030900416
A41: TIPA 312 MFG | B41: S723 | C41: =C12/$B$28 -> 0.083586841
B42: S724 | C42: =C13/$B$28 -> 0.023317418
A43: TIPA 312MFGW | B43: S723 | C43: =C14/$B$29 -> 0.076250921
B44: S724 | C44: =C15/$B$29 -> 0.021270987

Sheet Laminated bags - Sales
Q1: ה NF יותר יקר מה FG בגלל אחוזי הרווחיות השונים בין הסיגמנטים
C3: Dimenssions
C4: Height (mm) | D4: Width(mm) | E4: Base (mm) | F4: Flap (mm) | G4: Web Width (mm) | M4: מ"א נפולת ל - SET UP | P4: Euro
C5: =C20 -> 254 | D5: =C21 -> 254 | E5: =C22 -> 76.2 | F5: =C23 -> 0 | G5: =2*C20+C22*2+C23 -> 660.4 | M5: =500+100 -> 600 | P5: 3.9
A8: Laminate cost | G8: Zipper cost | I8: Adhisive Tape | K8: Pouch production cost | Q8: 0.25
A9: Product | B9: Laminate | C9: Thickness (µ) | D9: Cost for ml | E9: Width (mm) | F9: Total laminate cost | G9: Zipper cost | H9: Total zipper cost | I9: Tape cost | J9: Total tape cost | K9: Set up | L9: Quantity | M9: Set up fall out | N9: Set up cost per pouch | O9: Pouch production cost | P9: Total cost per pouch | Q9: Price for customer | S9: SDR Cost per bag
A10: =+C18 -> Zipper pouch | B10: ='Laminate for Bags - Sales'!A3 -> 608W | C10: =C27 -> 100 | D10: =IF(C25="PR",'Laminate for Bags - Sales'!I26,'Laminate for Bags - Sales'!I33) -> 1.3964766 | E10: =$D5/1000 -> 0.254 | F10: =E10*D10 -> 0.35470507 | G10: =IF(ISNUMBER(SEARCH("zipper",A10))=TRUE,'[3]List of names'!T3,"") -> 0.169 | H10: =IF(ISNUMBER(SEARCH("zipper",A10))=TRUE,G10*E10,"") -> 0.042926 | L10: =C24 -> 100000 | M10: =IF(H10="",M5*(D10),M5*(D10+H10)) -> 863.64159 | N10: =M10/L10 -> 0.0086364159 | O10: =0.41/1.16 -> 0.35344828 | P10: =IF(AND(H10="",J10=""),O10+N10+F10,IF(AND(H10="",J10<>""),O10+N10+J10+F10,IF(AND(H10<>"",J10=""),O10+N10+H10+F10,O10+N10+J10+H10+F10))) -> 0.75971576 | Q10: =$P10/(1-$Q$8) -> 1.0129543 | S10: =O10+SUM('Laminate for Bags - Sales'!Q9:Q11)*D5/1000 -> 0.39253785
E11: =D10*E10 -> 0.35470507
B15: Laminate Pouch
B17: Laminate type | C17: Laminate608W | D17: For Side gusset pouch
B18: Bag Type | C18: Zipper pouch
B19: Food grade | C19: FG
B20: Height of bag | C20: =10*25.4 -> 254 | D20: Width
B21: Width of bag | C21: =10*25.4 -> 254 | D21: Height
B22: Base Gusset/2 | C22: =3*25.4 -> 76.2 | D22: Side gusset*2 | E22: MOQ | F22: =IF(C17="Laminate608W",2000/'Laminate for Bags - Sales'!Q28, IF(C17="Laminate608",750/'Laminate for Bags - Sales'!Q28,500/'Laminate for Bags - Sales'!Q28)) -> 87818.63
B23: Flap | C23: 0 | E23: Total Weight | F23: =C24*'Laminate for Bags - Sales'!Q28 -> 2277.4211
B24: Amount | C24: 100000
B25: Printed | C25: PR
B26: Number of Colurs | C26: 5 to 8
B27: Thickness (µ) | C27: 100
B29: Check amount | C29: =IF(C24>=F22,1,"X") -> 1
B30: Price per bag EXW Italy | C30: =IF(C31*C24>50000,"Higher than 50K",C31) -> Higher than 50K
B31: Price per bag € | C31: =Q10 -> 1.0129543
B32: Total order price | C32: =C30*C29*C24 -> #VALUE!
B34: Cost per bag | C34: =P10 -> 0.75971576
B36: Price per bag $ | C36: =+C31*1.17 -> 1.1851566 | D36: =P10*1.17 -> 0.88886744
B37: Total order price | C37: =+C36*C24 -> 118515.66
C41: MOQ - KG
B42: Laminate106 | C42: 500
B43: Laminate607 | C43: 500
B44: Laminate608 | C44: 750
B45: Laminate608W | C45: 2000
B56: Open Bag | C56: Open Pouch
B57: Open SUP | C57: SUP
B58: Open bag with Flap | C58: Resealable Pouch
B59: SUP with zipper | C59: SUP | D59: If the closure is with Zipper
B60: Gusset bag | C60: Side gusset pouch
B61: Open bag with Zipper | C61: Zipper pouch

Sheet Laminate for Bags  - Sales
E1: Quote in | G1: Units | H1: ='Laminated bags - Sales'!C24 -> 100000
A2: Laminate | B2: Layer | C2: Laminate structure | D2: Width of reel asked | E2: Width Used | G2: FG/NF | H2: Laminate length | I2: PR/ NonPR | J2: No of paints | K2: Lemination Width (mm) | L2: Thickness (µ) | M2: Density | N2: Weight (kg) | O2: Raw material Cost | P2: TRANSPORTATION | Q2: Cost (€) | R2: Cost ($) | T2: Cost Per KG | V2: Film weight per bag | W2: מחיר הדפסה למ"א | X2: מ"א מודפס
A3: =IF('Laminated bags - Sales'!C17="Laminate607",607,IF('Laminated bags - Sales'!C17="Laminate608",608,IF('Laminated bags - Sales'!C17="Laminate418",418,IF('Laminated bags - Sales'!C17="Laminate608W","608W",IF('Laminated bags - Sales'!C17="Laminate106",106,IF('Laminated bags - Sales'!C17="Laminate428",428,IF('Laminated bags - Sales'!C17="Laminate819",819,IF('Laminated bags - Sales'!C17="Laminate823",823,IF('Laminated bags - Sales'!C17="Laminate618",618,"Check"))))))))) -> 608W | B3: =IF(C3<>"","A","") -> A | C3: =IF(A3=W608,"Tipa302WFG",IF(A3=418,"Tipa312Met",IF(A3=428,"Tipa312Met",IF(A3=823,"Tipa312Met","Tipa302FG")))) -> Tipa302FG | D3: ='Laminated bags - Sales'!G5 -> 660.4 | E3: =IF(OR(A3<>"608W",A3<>608),IF((K4-29)/D3>6,D3*6,IF((K4-29)/D3>5,D3*5,IF((K4-29)/D3>4,D3*4,IF((K4-29)/D3>3,D3*3,IF((K4-29)/D3>2,D3*2,D3))))),MAX(750,IF((K4-29)/D3>6,D3*6,IF((K4-29)/D3>5,D3*5,IF((K4-29)/D3>4,D3*4,IF((K4-29)/D3>3,D3*3,IF((K4-29)/D3>2,D3*2,D3))))))) -> 660.4 | G3: ='Laminated bags - Sales'!C19 -> FG | H3: =H1*'Laminated bags - Sales'!C21/1000 -> 25400 | I3: ='Laminated bags - Sales'!C25 -> PR | J3: ='Laminated bags - Sales'!C26 -> 5 to 8 | K3: 790 | L3: =IF(C5<>"",L8-SUM(L4:L5,6),L8-SUM(L4:L5,3)) -> 71 | M3: =VLOOKUP(C3,'[3]List of names'!L:N,3,0) -> 1.25 | N3: =IF(C3="PAPER",42/1000*$K3/1000,M3*1000*(L3/1000000)*($K3/1000)) -> 0.0701125 | O3: =IF(E3>950,'[3]Film -Summary'!Q25*1.25,'[3]Film -Summary'!Q25) -> 6.1893378 | P3: =VLOOKUP(C3,'[3]List of names'!$L$2:$M$10,2,FALSE)+$Q$31 -> 4.45 | Q3: =N3*(O3+P3) -> 0.74595057 | R3: =Q3*USD -> #REF! | T3: =(O3+P3)*N3/$N$8 -> 7.2706648 | V3: =1.25*(L3/1000)*(E3/1000)*'Laminated bags - Sales'!C21/1000 -> 0.014887067 | W3: =Y3/X3 -> 0.0915768 | X3: =IF(A3=608,1/N8,1/N4) -> 38.219287 | Y3: =IF(A3=608,Y11*Y10,IF(J3="1 to 4",Y7,Y8)) -> 3.5 | Z3: הדפסה לק"ג | AA3: כמות שכבות | AB3: מחיר לק"ג
B4: =IF(C4<>"","B","") -> B | C4: =VLOOKUP(A3,'[3]List of names'!$F$2:$G$11,2,0) -> NKR | K4: 790 | L4: =HLOOKUP(C4,'[3]List of names'!B15:E16,2,0) -> 23 | M4: =VLOOKUP(C4,'[3]List of names'!L:N,3,0) -> 1.44 | N4: =IF(C4="PAPER",42/1000*$K4/1000,M4*1000*(L4/1000000)*($K4/1000)) -> 0.0261648 | O4: =VLOOKUP(C4,'[3]Raw material summary'!$I$11:$J$17,2,0) -> 7.95 | P4: =VLOOKUP(C4,'[3]List of names'!$L$2:$M$10,2,FALSE)+$Q$31 -> 4.6 | Q4: =N4*(O4+P4) -> 0.32836824 | R4: =Q4*USD -> #REF! | T4: =(O4+P4)*N4/$N$8 -> 3.2005544 | W4: =Y4/X4 -> 0.15389595 | X4: =1/N8 -> 9.7468452 | Y4: 1.5 | Z4: למינציה לק"ג | AA4: =IF(OR(A3="608W",A3=608,A3=618,A3=418,A3=607),1,2) -> 1 | AB4: 2.5
B5: =IF(C5<>"","C","") -> C | C5: =IF(VLOOKUP(A3,'[3]List of names'!F2:H11,3,FALSE)=0,"",VLOOKUP(A3,'[3]List of names'!F2:H11,3,FALSE)) -> PBAT | K5: 790 | L5: =_xlfn.IFNA(HLOOKUP(C5,'[3]List of names'!B15:E16,2,0),0) -> 0 | M5: =IF(C5="",0,VLOOKUP(C5,'[3]List of names'!L2:N7,3,0)) -> 1.25 | N5: =IF(C5="","",IF(C5="PAPER",50/1000*$K5/1000,M5*1000*(L5/1000000)*($K5/1000))) -> 0 | O5: =VLOOKUP(C5,'[3]Raw material summary'!$I$11:$J$17,2,0) -> 5.5 | P5: =VLOOKUP(C5,'[3]List of names'!$L$2:$M$10,2,FALSE)+$Q$31 -> 4.45 | Q5: =IF(C5="","",N5*(O5+P5)) -> 0 | R5: =IF(C5="","",Q5*USD) -> #REF! | T5: =IF(C5="","",(O5+P5)*N5/$N$8) -> 0 | W5: =Y5/X5 -> 0 | X5: =1/N8 -> 9.7468452 | Y5: =IF('Laminated bags - Sales'!C25="PR",0,0.4)*Y10 -> 0 | Z5: חיתוך לק"ג
C6: ADHISIVE | N6: =IF(A3=608,0,(K3/1000*0.004*IF(B5="C",2,1))) -> 0.00632 | O6: 4.5 | P6: =Q31 -> 4.25 | Q6: =N6*(O6+P6) -> 0.0553 | R6: =Q6*USD -> #REF! | T6: =(O6+P6)*N6/$N$8 -> 0.53900054
C7: HARDENER | Q7: =N7*(O7+P7) -> 0 | R7: =Q7*USD -> #REF! | T7: =(O7+P7)*N7/$N$8 -> 0 | W7: =W4*X4 -> 1.5 | Y7: =IF(L18>1000,2.5,IF(L18>500,3,3.5))*Y10 -> 3 | Z7: מחיר הדפסה 1-4
A8: =A3 -> 608W | C8: =COUNTA(C3:C5) -> 3 | E8: =COUNTIF(C3:C5,"") -> 0 | G8: Lemingth length width used | H8: =H3/(ROUNDDOWN(K3/D3,0)) -> 25400 | K8: =SUMPRODUCT(K3:K5,L3:L5)/(L8-IF(AA4=2,6,3)) -> 765.56701 | L8: ='Laminated bags - Sales'!C27 -> 100 | N8: =SUM(N3:N7) -> 0.1025973 | P8: Total materials cost | Q8: =SUM(Q3:Q7) -> 1.1296188 | R8: =Q8*USD -> #REF! | T8: =SUM(T3:T7) -> 11.01022 | Y8: =IF(L18>1000,3,IF(L18>500,3.5,4))*Y10 -> 3.5 | Z8: מחיר הדפסה 5-8
E9: =IF(OR((680-D3*1)<120,AND((680-D3*2)<120,(680-D3*2)>0),AND((680-D3*3)<120,(680-D3*3)>0)),680,0) -> 680 | P9: Lamination | Q9: =+W4 -> 0.15389595 | R9: =Q9*USD -> #REF! | T9: =Y4 -> 1.5
B10: 4 | C10: EURO | E10: =IF(680-D3*1<120,680,0) -> 680 | M10: =+N3/N8 -> 0.68337568 | P10: Slitting | R10: =Q10*USD -> #REF! | T10: =Y5 -> 0 | Y10: =IF(L19<100,2,IF(L19<200,1.75,IF(L19<250,1.5,1))) -> 1 | Z10: מקדם מתחת ל300 ק"ג
B11: 3.6 | C11: $ | M11: =+M10*L19 -> 1780.8575 | P11: Printing | R11: =Q11*USD -> #REF! | T11: =Y3*N4/N8 -> 0.89258489 | Y11: 2.5 | Z11: מחיר הדפסה DP | AA11: DP Price
N12: =100*N8 -> 10.25973 | P12: Total | Q12: =SUM(Q8:Q11) -> 1.2835148 | R12: =SUM(R8:R11) -> #REF! | T12: =SUM(T8:T11) -> 13.402805 | Y12: 1.275 | Z12: למינציה DP
A13: Impression details | H13: Gross profit | I13: COST | K13: Cost per ml | L13: =$Q13/ROUNDDOWN((K8-30)/D3,0) -> 1.3964766 | M13: =L13*USD -> #REF! | P13: Total + 10% | Q13: =Q8*(1+Q17)+SUM(Q9:Q11) -> 1.3964766 | R13: =R12*1.1 -> #REF! | T13: =T12*1.1 -> 14.743085
A14: Width | B14: 300 | C14: This is the height of the bag | H14: =IF(C32="NF",30%,25%) -> 0.25 | K14: Cost per kg | L14: =$L13*$L22 -> 13.611242 | M14: =L14*USD -> #REF! | T14: =T13*(K3/E3) -> 17.636337
A15: Length | B15: 250 | C15: This is the width of the bag | I15: SELL | K15: Price per ml | L15: =$L13/(1-$H14) -> 1.8619689 | M15: =L15*USD -> #REF!
K16: Price per kg | L16: =L14/(1-H14) -> 18.148322 | M16: =L16*USD -> #REF! | N16: =L16/L15 -> 9.7468452 | AB16: "680,900,1100"
A17: Reel details | L17: =(L16-L14)/L16 -> 0.25 | P17: Waste assumption Printed | Q17: 0.1
A18: Width | B18: =C35 -> 0 | C18: This is the height of the bag*2 | K18: Printed KG | L18: =L19*L4/L8 -> 599.37343 | P18: Waste assumption Non Printed | Q18: 0.1
A19: Length | B19: =C37 -> 0 | C19: to check if there is any length limitation - Must be filled!!! | K19: Total KG | L19: =N8/ROUNDDOWN((K3-29)/D3,0)*H3 -> 2605.9714 | M19: =+L19*N3/N8 -> 1780.8575
A21: Waste assumptions | C21: Number of works | D21: Waste per work | K21: Ml & Lem used width of reel in kg | L21: =1/N8 -> 9.7468452
A22: 1st laminate | B22: 1000 | C22: 4 | D22: =B22/C22 -> 250 | K22: Ml & Lem Asked width of reel in kg | L22: =1/N8*ROUNDDOWN(E3/D3,0) -> 9.7468452 | P22: Number of impression | Q22: =IF(G1="impression",ROUNDDOWN(K3/D3,0)*1000/B15,"NA") -> NA
A23: 2nd laminate | B23: 1000 | C23: 4 | D23: =B23/C23 -> 250 | H23: Printed Waste Assumption | P23: Cost per impressiom | Q23: =IF(G1="Impression",Q13/Q22,"NA") -> NA
A24: Prining | B24: 1000 | C24: 1 | D24: =B24/C24 -> 1000 | I24: Eur | K24: USD | P24: Price Per impression | Q24: =Q23*1.25 -> #VALUE!
A25: Reel change | B25: 50 | C25: evrey 3K Meter | I25: Cost | J25: Sale price | K25: Cost | L25: Sale price
A26: Converting | B26: 500 | C26: Set up | H26: ML | I26: =L13 -> 1.3964766 | J26: =L15 -> 1.8619689 | K26: =I26*USD -> #REF! | L26: =J26*USD -> #REF!
A27: Converting process | B27: 0.1 | C27: Based on the run length | D27: =5%+3% -> 0.08 | E27: =7%+3% -> 0.1 | G27: =6%+3% -> 0.09 | H27: KG | I27: =L14 -> 13.611242 | J27: =L16 -> 18.148322 | K27: =I27*USD -> #REF! | L27: =J27*USD -> #REF!
P28: Weight of bag | Q28: =N8*D3/E3*((E3+30)/K3)*'Laminated bags - Sales'!C21/1000 -> 0.022774211
H29: Non Printed waste Assumption
I31: Eur | K31: USD | P31: Shipment addition | Q31: =IF(L19<1000,2,IF(L19<3000,2,1.5))+15*0.15 -> 4.25
G32: =H14 -> 0.25 | I32: Cost | J32: Sale price | K32: Cost | L32: Sale price
H33: ML | I33: =(Q8*(1+Q18)+SUM(Q9:Q11))/ROUNDDOWN((K3-30)/D3,0) -> 1.3964766 | J33: =I33*(1+$G$32) -> 1.7455958 | K33: =I33*USD -> #REF! | L33: =J33*USD -> #REF!
H34: KG | I34: =$I33*$L22 -> 13.611242 | J34: =I34*(1+$G$32) -> 17.014052 | K34: =I34*USD -> #REF! | L34: =J34*USD -> #REF!

Sheet Laminate for reels  - Sales (2)
B1: Laminate608 W | C1: Tipa302WFG | E1: Quote in | G1: =C38 -> Ml | H1: =C39 -> 5000
A2: Laminate | B2: Layer | C2: Laminate structure | D2: Width of reel asked | E2: Width Used | F2: length of impression | G2: FG/NF | H2: Laminate length (m) width asked | I2: PR/ NonPR | J2: No of paints | K2: Lemination Width (mm) | L2: Thickness (µ) | M2: Density | N2: Weight (kg) | O2: Raw material Cost | P2: TRANSPORTATION | Q2: Cost (€) | R2: Cost ($) | T2: Cost Per KG | W2: מחיר הדפסה למ"א | X2: מ"א מודפס | AB2: SDR Price
A3: =IF(C36="Laminate607",607,IF(C36="Laminate608",608,IF(C36="Laminate418",418,IF(C36="Laminate608W","608W",IF(C36="Laminate106",106,IF(C36="Laminate428",428,IF(C36="Laminate819",819,IF(C36="Laminate823",823,IF(C36="Laminate618",618,"Check"))))))))) -> 819 | B3: =IF(C3<>"","A","") -> A | C3: =IF(C36="Laminate608W","Tipa302WFG",IF(C36="Laminate418","Tipa312Met",IF(C36="Laminate428","Tipa312Met",IF(C36="Laminate823","Tipa312Met","Tipa302FG")))) -> Tipa302FG | D3: =IF(G1="Impression",B14,B18) -> 760 | E3: =IF(OR(A3<>"608W",A3<>608),IF((K4-29)/D3>6,D3*6,IF((K4-29)/D3>5,D3*5,IF((K4-29)/D3>4,D3*4,IF((K4-29)/D3>3,D3*3,IF((K4-29)/D3>2,D3*2,D3))))),MAX(750,IF((K4-29)/D3>6,D3*6,IF((K4-29)/D3>5,D3*5,IF((K4-29)/D3>4,D3*4,IF((K4-29)/D3>3,D3*3,IF((K4-29)/D3>2,D3*2,D3))))))) -> 760 | F3: =IF(G1="Impression",B15,"") | G3: =C37 -> FG | H3: =IF(G1="Ml",H1,IF(G1="KG",(1/N8*ROUNDDOWN((K8-30)/D3,0))*H1,H1*F3/1000)) -> 5000 | I3: =C43 -> Non PR | J3: =C44 -> 0 | K3: =IF(OR(A3="608W",A3=608),E3+40*2,E3+50) -> 810 | L3: =IF($AA$4=1,L8-SUM(L4:L5,3),L8-SUM(L4:L5,6)) -> 4 | M3: =VLOOKUP(C3,'[1]List of names'!L:N,3,0) -> 1.25 | N3: =IF(C3="PAPER",42/1000*$K3/1000,M3*1000*(L3/1000000)*($K3/1000)) -> 0.00405 | O3: =IF(E3<950,'[1]Film -Summary'!Q35,'[1]Film -Summary'!Q35*1.25) -> #N/A | P3: =VLOOKUP(C3,'[1]List of names'!$L$2:$M$10,2,FALSE)+Q32 -> 4.95 | Q3: =N3*(O3+P3) -> #N/A | R3: =Q3*USD -> #N/A | T3: =(O3+P3)*N3/$N$8 -> #N/A | W3: =Y3/X3 -> 0.1073088 | X3: =IF(OR(A3="608W",A3=608),1/N8,1/N4) -> 37.275601 | Y3: =IF(OR(A3="608W",A3=608),Y11*Y10,IF(J3="1 to 4",Y7,Y8)) -> 4 | Z3: הדפסה לק"ג | AA3: כמות שכבות | AB3: מחיר לק"ג
B4: =IF(C4<>"","B","") -> B | C4: =VLOOKUP(A3,'[1]List of names'!$F$2:$G$11,2,0) -> NKR | K4: =IF(D3<300,D3*4+50,IF(D3<400,D3*3+50,IF(D3<600,D3*2+50,D3+50))) -> 810 | L4: {=IF(C4="NKR",23,IF(C4="NKME",20,IF(C4="Tipa312Met",25,NA)))} -> 23 | M4: =VLOOKUP(C4,'[1]List of names'!L:N,3,0) -> 1.44 | N4: =IF(C4="PAPER",42/1000*$K4/1000,M4*1000*(L4/1000000)*($K4/1000)) -> 0.0268272 | O4: =VLOOKUP(C4,'[1]Raw material summary'!$I$10:$K$16,IF($K$3<900,2,3),0) -> 7.95 | P4: =VLOOKUP(C4,'[1]List of names'!$L$2:$M$7,2,FALSE)+Q32 -> 5.1 | Q4: =N4*(O4+P4) -> 0.35009496 | R4: =Q4*USD -> 0.38510446 | T4: =(O4+P4)*N4/$N$8 -> 5.0777256 | W4: =Y4/X4 -> 0.28957824 | X4: =1/N8 -> 14.503852 | Y4: =IF(OR(A3=608,A3="608W"),AA4*Y12*Y10,Y12*AA4*Y10) -> 4.2 | Z4: למינציה לק"ג | AA4: =IF(OR(A3="608W",A3=608,A3=618,A3=418),1,2) -> 2 | AB4: 2.5
B5: =IF(C5<>"","C","") -> C | C5: =IF(VLOOKUP(A3,'[1]List of names'!F2:H11,3,FALSE)=0,"",VLOOKUP(A3,'[1]List of names'!F2:H11,3,FALSE)) -> Paper | K5: =IF(D3<300,D3*4+50,IF(D3<400,D3*3+50,IF(D3<600,D3*2+50,D3+50))) -> 810 | L5: =IF(C5="","",IF(C5="NKR",23,IF(C5="NKME",20,IF(C5="Paper",67,IF(C5="PBAT",INDEX('[1]List of names'!$F$34:$F$40,MATCH($L$8,'[1]List of names'!$D$34:$D$40,0)),IF(C5="",0,"NA")))))) -> 67 | M5: =IF(C5="",0,VLOOKUP(C5,'[1]List of names'!L2:N7,3,0)) -> 1 | N5: =IF(C5="","",IF(C5="PAPER",42/1000*$K5/1000,M5*1000*(L5/1000000)*($K5/1000))) -> 0.03402 | O5: =IF(C5="",0,VLOOKUP(C5,'[1]Raw material summary'!$I$10:$K$16,IF($K$3<900,2,3),0)) -> 1.31 | P5: =IF(C5="",0,VLOOKUP(C5,'[1]List of names'!$L$2:$M$7,2,FALSE)) -> 0.3 | Q5: =IF(C5="","",N5*(O5+P5)) -> 0.0547722 | R5: =IF(C5="","",Q5*USD) -> 0.06024942 | T5: =IF(C5="","",(O5+P5)*N5/$N$8) -> 0.79440789 | W5: =Y5/X5 -> 0.0517104 | X5: =1/N8 -> 14.503852 | Y5: 0.75 | Z5: חיתוך לק"ג
C6: ADHISIVE | N6: =IF(A3=608,0,(K3/1000*0.0025*IF(B5="C",2,1))) -> 0.00405 | O6: 4.5 | P6: =0.2+Q32 -> 4.95 | Q6: =N6*(O6+P6) -> 0.0382725 | R6: =Q6*USD -> 0.04209975 | T6: =(O6+P6)*N6/$N$8 -> 0.55509868
C7: HARDENER | Q7: =N7*(O7+P7) -> 0 | R7: =Q7*USD -> 0 | T7: =(O7+P7)*N7/$N$8 -> 0 | Y7: 3.5 | Z7: מחיר הדפסה 1-4
A8: =A3 -> 819 | C8: =COUNTA(C3:C5) -> 3 | E8: =COUNTIF(C3:C5,"") -> 0 | G8: Lemingth length width used | H8: =H3/(ROUNDDOWN(K3/D3,0)) -> 5000 | K8: =SUMPRODUCT(K3:K5,L3:L5)/IF(AA4=1,($L$8-3),($L$8-6)) -> 810 | L8: =C45 -> 100 | N8: =SUM(N3:N7) -> 0.0689472 | P8: Total materials cost | Q8: =SUM(Q3:Q7) -> #N/A | R8: =Q8*USD -> #N/A | T8: =SUM(T3:T7) -> #N/A | Y8: 4 | Z8: מחיר הדפסה 5-8
E9: =IF(OR((680-D3*1)<120,AND((680-D3*2)<120,(680-D3*2)>0),AND((680-D3*3)<120,(680-D3*3)>0)),680,0) -> 680 | L9: =K3*L3+K4*L4 -> 21870 | P9: Lamination | Q9: =0.06 -> 0.06 | R9: =Q9*USD -> 0.066 | T9: =+Y4 -> 4.2
B10: 4 | C10: EURO | E10: =IF(680-D3*1<120,680,0) -> 680 | F10: =IF(C5="NKR",19,IF(C5="NKME",20,IF(C5="",0,"NA"))) -> NA | K10: =IF(OR(A3=607,A3=608),'[1]SDR price list'!Y5,'[1]SDR price list'!Y21) -> 910 | P10: Slitting | Q10: =W5 -> 0.0517104 | R10: =Q10*USD -> 0.05688144 | T10: =Y5 -> 0.75 | Y10: =IF(L19<300,2,IF(L19<750,1.75,IF(L19<1500,1.5,1))) -> 1.75 | Z10: מקדם מתחת ל300 ק"ג
B11: 3.6 | C11: $ | P11: Printing | Q11: =87.8/1000 -> 0.0878 | R11: =Q11*USD -> 0.09658 | T11: =IF(I3="PR",Y3*N4/N8,0) -> 0 | Y11: 2.5 | Z11: מחיר הדפסה DP | AA11: DP Price
D12: =IF(C36=OR("Laminate418","Laminate428","Laminate823"),"Tipa312Met") -> #VALUE! | N12: =100*N8 -> 6.89472 | P12: Total | Q12: =SUM(Q8:Q11) -> #N/A | R12: =SUM(R8:R11) -> #N/A | T12: =SUM(T8:T11) -> #N/A | Y12: 1.2 | Z12: למינציה DP
A13: Impression details | H13: Gross profit | I13: COST | K13: Cost per ml | L13: =$Q13/ROUNDDOWN((K8-30)/D3,0) -> #N/A | M13: =L13*$B$10/$B$11 -> #N/A | P13: Total + 10% | Q13: =Q8*(1+Q17)+SUM(Q9:Q11) -> #N/A | R13: =R12*(1.1) -> #N/A | T13: =T8*(1+Q17)+SUM(T9:T11) -> #N/A
A14: Width | B14: =C40 -> 760 | C14: This is the height of the bag | H14: 0.2 | K14: Cost per kg | L14: =$L13*$L22*K8/E3 -> #N/A | M14: =L14*$B$10/$B$11 -> #N/A | T14: =T13*(K8/E3) -> #N/A
A15: Length | B15: 110 | C15: This is the width of the bag | I15: SELL | K15: Price per ml | L15: =$L13/(1-$H14) -> #N/A | M15: =L15*$B$10/$B$11 -> #N/A | X15: Total Weight | Y15: Total Cost
K16: Price per kg | L16: =L14/(1-H14) -> #N/A | M16: =L16*$B$10/$B$11 -> #N/A | T16: =T8/T12 -> #N/A | X16: =$H$8*N3 -> 20.25 | Y16: =X16*(O3+P3) -> #N/A | AB16: "680,900,1100"
A17: Reel details | P17: Waste assumption Printed | Q17: =IF(A3=607,(D24*L4/L8+D23+D27*H8)/H8,(D24*L4/L8+D23+D22*0.8+D27*H8)/H8) -> 0.186 | X17: =$H$8*N4 -> 134.136 | Y17: =X17*(O4+P4) -> 1750.4748
A18: Width | B18: =C40 -> 760 | C18: This is the height of the bag*2 | K18: Printed KG | L18: =L19*L4/L8 -> 79.28928 | P18: Waste assumption Non Printed | Q18: =IF(C5="",(D23+D27*H8)/H8,(D23+D22*0.8+D27*H8)/H8) -> 0.14 | X18: =$H$8*N5 -> 170.1 | Y18: =X18*(O5+P5) -> 273.861
A19: Length | B19: =C42 -> 0 | C19: to check if there is any length limitation - Must be filled!!! | K19: Total KG | L19: =N8/ROUNDDOWN((K8-29)/D3,0)*H3 -> 344.736 | M19: =+L19*N3/N8 -> 20.25 | X19: =$H$8*N6 -> 20.25 | Y19: =X19*(O6+P6) -> 191.3625
K20: Net KG | L20: =N8/ROUNDDOWN(K8/D3,0)*(E3/K8)*H1 -> 323.456 | X20: =$H$8*N7 -> 0 | Y20: =X20*O7 -> 0
A21: Waste assumptions | C21: Number of works | D21: Waste per work | K21: Ml & Lem used width of reel in kg | L21: =1/N8 -> 14.503852 | X21: =SUM(X16:X20) -> 344.736 | Y21: =SUM(Y16:Y20) -> #N/A
A22: 1st laminate | B22: 1000 | C22: 4 | D22: =B22/C22 -> 250 | K22: Ml & Lem Asked width of reel in kg | L22: =1/N8*ROUNDDOWN(K8/D3,0) -> 14.503852 | P22: Number of impression | Q22: =ROUNDDOWN(K3/D3,0)*1000/B15 -> 9.0909091 | X22: Waste of width | Y22: =+(K3/E3*T13-T13)*L19 -> #N/A
A23: 2nd laminate | B23: 1000 | C23: 4 | D23: =B23/C23 -> 250 | H23: Printed Waste Assumption | P23: Cost per impressiom | Q23: =Q13/Q22 -> #N/A | X23: SDR | Y23: =X21*SUM(T9:T11) -> 1706.4432
A24: Prining | B24: 1000 | C24: 1 | D24: =B24/C24 -> 1000 | I24: Eur | K24: USD | P24: Price Per impression | Q24: =Q23*1.25 -> #N/A | R24: =Q24*1.16 -> #N/A | X24: Waste | Y24: =IF(C43="PR",Y21*Q17,Y21*Q18) -> #N/A
A25: Reel change | B25: 50 | C25: evrey 3K Meter | I25: Cost | J25: Sale price | K25: Cost | L25: Sale price | X25: Total Cost | Y25: =SUM(Y21:Y24) -> #N/A
A26: Converting | B26: 500 | C26: Set up | H26: ML | I26: =L13 -> #N/A | J26: =L15 -> #N/A | K26: =I26*$O$29 -> #N/A | L26: =J26*$O$29 -> #N/A | P26: Meter MOQ | Q26: =IF(C36="Laminate608",750/N8*(E3/D3),500/N8*(E3/D3)) -> 7251.9261 | X26: Total Price | Y26: =C50 -> #N/A
A27: Converting process | B27: 0.1 | C27: Based on the run length | D27: 0.05 | H27: KG | I27: =L14 -> #N/A | J27: =L16 -> #N/A | K27: =I27*$O$29 -> #N/A | L27: =J27*$O$29 -> #N/A | X27: Profit | Y27: =Y26-Y25 -> #N/A
O28: Euro to dollar rate | Y28: =Y27/Y26 -> #N/A
H29: Non Printed waste Assumption | O29: 1.17
I31: Eur | K31: USD
B32: Laminat Reel 607, 106 | C32: MOQ = 500KG | G32: =H14 -> 0.2 | I32: Cost | J32: Sale price | K32: Cost | L32: Sale price | P32: Shipment addition | Q32: =IF(L20<1000,2.5,IF(L20<3000,2,1.5))+15*0.15 -> 4.75
B33: Laminat Reel 608 | C33: MOQ = 750KG | H33: ML | I33: =(Q8*(1+Q18)+SUM(Q9:Q11))/ROUNDDOWN((K3-30)/D3,0) -> #N/A | J33: =I33/(1-$G$32) -> #N/A | K33: =I33*$O$29 -> #N/A | L33: =J33*$O$29 -> #N/A
B34: Laminat Reel 608W | C34: MOQ = 2000KG | H34: KG | I34: =$I33*$L22*K8/E3 -> #N/A | J34: =I34/(1-$G$32) -> #N/A | K34: =I34*$O$29 -> #N/A | L34: =J34*$O$29 -> #N/A
B36: Laminate type | C36: Laminate819 | I36: =I33*800 -> #N/A
B37: Food grade | C37: FG
B38: Quote by | C38: Ml | D38: Meter MOQ | E38: =IF(C36="Laminate608w",2000/N8*(E3/D3),IF(C36="Laminate608",750/N8*(E3/D3),500/N8*(E3/D3))) -> 7251.9261
B39: Amount | C39: 5000 | D39: KG MOQ | E39: =IF(C36="Laminate608W",2000,IF(C36="Laminate608",750,500)) -> 500 | I39: QTY | J39: Cost | K39: Price
B40: Width of reel | C40: 760 | D40: Total KG | E40: =+L19 -> 344.736 | H40: Z10771.00023-000 | I40: 5000 | J40: 11.485134 | K40: 14.356417 | L40: =K40*I40 -> 71782.087
B41: Length limitation <50Kg (Y/N) | C41: Y | D41: (*) Min is 500 Meter | H41: Z10771.00023-000 | I41: =I40*2 -> 10000 | J41: =$I$34 -> #N/A | K41: =$J$34 -> #N/A | L41: =K41*I41 -> #N/A | M41: =K41/K40-1 -> #N/A
B42: Length Limit | D42: (*) Up to 1,150 width | H42: Z10771.00023-000 | I42: =I40*3 -> 15000 | J42: =$I$34 -> #N/A | K42: =$J$34 -> #N/A | L42: =K42*I42 -> #N/A | M42: =K42/K41-1 -> #N/A
...

Sheet Step by Step
B2: 📋 FILM PRICING LIST - STEP BY STEP GUIDE
B3: How to use the Film Pricing calculator
B5: 🔄 PRICING WORKFLOW
B7: STEP 1 | C7: → | D7: STEP 2 | E7: → | F7: STEP 3 | G7: → | H7: STEP 4 | I7: → | J7: STEP 5
B8: 📝 INPUT | D8: ⚙️ SPECS | F8: 💰 COSTS | H8: 📦 SHIP | J8: 💵 PRICE
B11: 📝 DETAILED STEPS
B13: Step | C13: Action | D13: Column | E13: Example | F13: Notes
B14: 1️⃣ | C14: Select Film Type | D14: A | E14: TIPA 302FG | F14: Dropdown list
B15: 2️⃣ | C15: Enter Width | D15: B | E15: 406 mm | F15: Width in mm
B16: 3️⃣ | C16: Enter Thickness | D16: C | E16: 20 µ | F16: Dropdown list
B17: 4️⃣ | C17: Enter Weight | D17: E | E17: 500 Kg | F17: Order qty (Kg)
B18: 5️⃣ | C18: Weight Override | D18: F | E18: 500 Kg | F18: Optional
B19: 6️⃣ | C19: Shipping Dest. | D19: S | E19: EU/USA | F19: Dropdown list
B20: 7️⃣ | C20: Review Price | D20: W | E20: Auto | F20: Final price/Kg
B21: 8️⃣ | C21: Compare Margins | D21: X+ | E21: 25%, 30% | F21: Multiple options
B24: ⚡ AUTO-CALCULATIONS
B26: Calculation | C26: Formula Logic
B27: Length (Mr) | C27: Weight ÷ (Width × Thickness × Density)
B28: Production Cost | C28: Hourly Rate × Production Time
B29: Total Cost | C29: RM + Production + Depreciation + Waste + Ship
B30: Sell Price | C30: Total Cost × (1 + Margin %)
B33: 💡 QUICK TIPS
B35: ✓ Use dropdowns to avoid typos
B36: ✓ Higher weight = lower cost/Kg (economies of scale)
B37: ✓ Compare margin columns for pricing options
B38: ✓ Density auto-fills based on Film Type

Sheet BOM
A1: Film | B1: Ext | C1: Material | D1: Grade | E1: Serial Number | F1: Resin | G1: Thickness (µ) | H1: QTY | I1: Price (€/kg) | J1: Price Calculated(€) Thickness & QTY related | L1: Film | M1: Grade | N1: Serial Number | O1: Price Calculated(€) Thickness & QTY related | Q1: Film | R1: Price (€/kg) | S1: Price ($/kg) | U1: Film | V1: Material | W1: Grade | X1: Serial Number | Y1: Resin | Z1: Weighted QTY % | AA1: Film Total Check
A2: TIPA 302FG | B2: Ext. A (Out - Chillroll) | C2: PBSA | D2: =IF(C2="","",IFERROR(_xlfn.XLOOKUP(C2,HELPER!$A$2:$A$81,HELPER!$B$2:$B$81,""),D2)) -> FD92PM | E2: =IFERROR(_xlfn.XLOOKUP(D2,HELPER!$B:$B,HELPER!$C:$C,""),"") -> RMPM2 | F2: =IFERROR(_xlfn.XLOOKUP(D2,HELPER!$B:$B,HELPER!$D:$D,""),"") -> Resin 9C | G2: 8 | H2: 0.826 | I2: =IF(AND(H2<>"",IFERROR(_xlfn.XLOOKUP(D2,HELPER!$B:$B,HELPER!$E:$E,""),"")=""),"Missing price",IFERROR(_xlfn.XLOOKUP(D2,HELPER!$B:$B,HELPER!$E:$E,"")," ")) -> 6.75 | J2: =IFERROR(H2*(IF(G2=8,I2*HELPER!$G$2,BOM!I2*HELPER!$G$3))," ") -> 1.1151 | L2: {=IFERROR(_xlfn.LET(_xlpm.films,Table4[Film],_xlpm.grades,Table4[Grade],_xlpm.pairs,_xlfn._xlws.FILTER(_xlfn.HSTACK(_xlpm.films,_xlpm.grades),(_xlpm.films<>"")*(TRIM(_xlpm.grades)<>"")),_xlpm.uniquePairs,_xlfn.UNIQUE(_xlpm.pairs),_xlpm.sortedPairs,_xlfn._xlws.SORT(_xlpm.uniquePairs,1,1),INDEX(_xlpm.sortedPairs,ROWS($L$2:L2),1)),"")} -> PL202.1 | M2: {=IFERROR(_xlfn.LET(_xlpm.films,Table4[Film],_xlpm.grades,Table4[Grade],_xlpm.pairs,_xlfn._xlws.FILTER(_xlfn.HSTACK(_xlpm.films,_xlpm.grades),(_xlpm.films<>"")*(TRIM(_xlpm.grades)<>"")),_xlpm.uniquePairs,_xlfn.UNIQUE(_xlpm.pairs),_xlpm.sortedPairs,_xlfn._xlws.SORT(_xlpm.uniquePairs,1,1),INDEX(_xlpm.sortedPairs,ROWS($M$2:M2),2)),"")} -> FD92PM | N2: {=IF(OR(Table2[[#This Row],[Film]]="",Table2[[#This Row],[Grade]]=""),"",IFERROR(INDEX(Table4[Serial Number],MATCH(1,(Table4[Film]=Table2[[#This Row],[Film]])*(Table4[Grade]=Table2[[#This Row],[Grade]]),0)),""))} -> RMPM2 | O2: =IF(OR(Table2[[#This Row],[Film]]="",Table2[[#This Row],[Grade]]=""),"",SUMIFS(Table4[Price Calculated(€) Thickness & QTY related],Table4[Film],Table2[[#This Row],[Film]],Table4[Grade],Table2[[#This Row],[Grade]])) -> 3.25215 | Q2: {=IFERROR(INDEX(Table2[Film],MATCH(0,COUNTIF($Q$1:Q1,Table2[Film])+IF(Table2[Film]="",1,0),0)),"")} -> PL202.1 | R2: =SUMIF(Table2[Film],"TIPA 312 MFG",Table2[Price Calculated(€) Thickness & QTY related])+_xlfn.XLOOKUP("MET LUX ",HELPER!$A:$A,HELPER!$E:$E,0) -> 5.380588 | S2: =IFERROR(R2*HELPER!$AK$2," ") -> 6.2414821 | U2: PL202.1 | V2: PVOH | W2: BVE8049P | X2: BVE8049P | Y2: BVE8049P | Z2: {=SUMPRODUCT((BOM!$A$2:$A$391=U2)*(BOM!$F$2:$F$391=Y2)*BOM!$H$2:$H$391*BOM!$G$2:$G$391)/SUMPRODUCT((BOM!$A$2:$A$391=U2)*BOM!$H$2:$H$391*BOM!$G$2:$G$391)} -> 0.254 | AA2: =SUMIF(tblResinWeightedQty12[Film],tblResinWeightedQty12[[#This Row],[Film]],tblResinWeightedQty12[Weighted QTY %]) -> 1
A3: TIPA 302FG | B3: Ext. A (Out - Chillroll) | C3: PLA | D3: =IF(C3="","",IFERROR(_xlfn.XLOOKUP(C3,HELPER!$A$2:$A$81,HELPER!$B$2:$B$81,""),D3)) -> LX175 | E3: =IFERROR(_xlfn.XLOOKUP(D3,HELPER!$B:$B,HELPER!$C:$C,""),"") -> RMLX175 | F3: =IFERROR(_xlfn.XLOOKUP(D3,HELPER!$B:$B,HELPER!$D:$D,""),"") -> Resin 1A | G3: 8 | H3: 0.144 | I3: =IF(AND(H3<>"",IFERROR(_xlfn.XLOOKUP(D3,HELPER!$B:$B,HELPER!$E:$E,""),"")=""),"Missing price",IFERROR(_xlfn.XLOOKUP(D3,HELPER!$B:$B,HELPER!$E:$E,"")," ")) -> 3.17 | J3: =IFERROR(H3*(IF(G3=8,I3*HELPER!$G$2,BOM!I3*HELPER!$G$3))," ") -> 0.091296 | L3: {=IFERROR(_xlfn.LET(_xlpm.films,Table4[Film],_xlpm.grades,Table4[Grade],_xlpm.pairs,_xlfn._xlws.FILTER(_xlfn.HSTACK(_xlpm.films,_xlpm.grades),(_xlpm.films<>"")*(TRIM(_xlpm.grades)<>"")),_xlpm.uniquePairs,_xlfn.UNIQUE(_xlpm.pairs),_xlpm.sortedPairs,_xlfn._xlws.SORT(_xlpm.uniquePairs,1,1),INDEX(_xlpm.sortedPairs,ROWS($L$2:L3),1)),"")} -> PL202.1 | M3: {=IFERROR(_xlfn.LET(_xlpm.films,Table4[Film],_xlpm.grades,Table4[Grade],_xlpm.pairs,_xlfn._xlws.FILTER(_xlfn.HSTACK(_xlpm.films,_xlpm.grades),(_xlpm.films<>"")*(TRIM(_xlpm.grades)<>"")),_xlpm.uniquePairs,_xlfn.UNIQUE(_xlpm.pairs),_xlpm.sortedPairs,_xlfn._xlws.SORT(_xlpm.uniquePairs,1,1),INDEX(_xlpm.sortedPairs,ROWS($M$2:M3),2)),"")} -> LX175 | N3: {=IF(OR(Table2[[#This Row],[Film]]="",Table2[[#This Row],[Grade]]=""),"",IFERROR(INDEX(Table4[Serial Number],MATCH(1,(Table4[Film]=Table2[[#This Row],[Film]])*(Table4[Grade]=Table2[[#This Row],[Grade]]),0)),""))} -> RMLX175 | O3: =IF(OR(Table2[[#This Row],[Film]]="",Table2[[#This Row],[Grade]]=""),"",SUMIFS(Table4[Price Calculated(€) Thickness & QTY related],Table4[Film],Table2[[#This Row],[Film]],Table4[Grade],Table2[[#This Row],[Grade]])) -> 0.270084 | Q3: {=IFERROR(INDEX(Table2[Film],MATCH(0,COUNTIF($Q$1:Q2,Table2[Film])+IF(Table2[Film]="",1,0),0)),"")} -> PL202.2 | R3: =SUMIF(Table2[Film],"TIPA 312 MFG",Table2[Price Calculated(€) Thickness & QTY related])+_xlfn.XLOOKUP("MET LUX ",HELPER!$A:$A,HELPER!$E:$E,0) -> 5.380588 | S3: =IFERROR(R3*HELPER!$AK$2," ") -> 6.2414821 | U3: PL202.1 | V3: PLA | W3: LX175 | X3: RMLX175 | Y3: Resin 1A | Z3: {=SUMPRODUCT((BOM!$A$2:$A$391=U3)*(BOM!$F$2:$F$391=Y3)*BOM!$H$2:$H$391*BOM!$G$2:$G$391)/SUMPRODUCT((BOM!$A$2:$A$391=U3)*BOM!$H$2:$H$391*BOM!$G$2:$G$391)} -> 0.0852 | AA3: =SUMIF(tblResinWeightedQty12[Film],tblResinWeightedQty12[[#This Row],[Film]],tblResinWeightedQty12[Weighted QTY %]) -> 1
A4: TIPA 302FG | B4: Ext. A (Out - Chillroll) | C4: AB-PLA | D4: =IF(C4="","",IFERROR(_xlfn.XLOOKUP(C4,HELPER!$A$2:$A$81,HELPER!$B$2:$B$81,""),D4)) -> KAB59A | E4: =IFERROR(_xlfn.XLOOKUP(D4,HELPER!$B:$B,HELPER!$C:$C,""),"") -> RM A KAB59A | F4: =IFERROR(_xlfn.XLOOKUP(D4,HELPER!$B:$B,HELPER!$D:$D,""),"") -> Resin 8 | G4: 8 | H4: 0.015 | I4: =IF(AND(H4<>"",IFERROR(_xlfn.XLOOKUP(D4,HELPER!$B:$B,HELPER!$E:$E,""),"")=""),"Missing price",IFERROR(_xlfn.XLOOKUP(D4,HELPER!$B:$B,HELPER!$E:$E,"")," ")) -> 7.55 | J4: =IFERROR(H4*(IF(G4=8,I4*HELPER!$G$2,BOM!I4*HELPER!$G$3))," ") -> 0.02265 | L4: {=IFERROR(_xlfn.LET(_xlpm.films,Table4[Film],_xlpm.grades,Table4[Grade],_xlpm.pairs,_xlfn._xlws.FILTER(_xlfn.HSTACK(_xlpm.films,_xlpm.grades),(_xlpm.films<>"")*(TRIM(_xlpm.grades)<>"")),_xlpm.uniquePairs,_xlfn.UNIQUE(_xlpm.pairs),_xlpm.sortedPairs,_xlfn._xlws.SORT(_xlpm.uniquePairs,1,1),INDEX(_xlpm.sortedPairs,ROWS($L$2:L4),1)),"")} -> PL202.1 | M4: {=IFERROR(_xlfn.LET(_xlpm.films,Table4[Film],_xlpm.grades,Table4[Grade],_xlpm.pairs,_xlfn._xlws.FILTER(_xlfn.HSTACK(_xlpm.films,_xlpm.grades),(_xlpm.films<>"")*(TRIM(_xlpm.grades)<>"")),_xlpm.uniquePairs,_xlfn.UNIQUE(_xlpm.pairs),_xlpm.sortedPairs,_xlfn._xlws.SORT(_xlpm.uniquePairs,1,1),INDEX(_xlpm.sortedPairs,ROWS($M$2:M4),2)),"")} -> S723 | N4: {=IF(OR(Table2[[#This Row],[Film]]="",Table2[[#This Row],[Grade]]=""),"",IFERROR(INDEX(Table4[Serial Number],MATCH(1,(Table4[Film]=Table2[[#This Row],[Film]])*(Table4[Grade]=Table2[[#This Row],[Grade]]),0)),""))} -> RM TA45-08 S723 | O4: =IF(OR(Table2[[#This Row],[Film]]="",Table2[[#This Row],[Grade]]=""),"",SUMIFS(Table4[Price Calculated(€) Thickness & QTY related],Table4[Film],Table2[[#This Row],[Film]],Table4[Grade],Table2[[#This Row],[Grade]])) -> 0.3232 | Q4: {=IFERROR(INDEX(Table2[Film],MATCH(0,COUNTIF($Q$1:Q3,Table2[Film])+IF(Table2[Film]="",1,0),0)),"")} -> PL202.3 | R4: =SUMIF(Table2[Film],"TIPA 312 MFG",Table2[Price Calculated(€) Thickness & QTY related])+_xlfn.XLOOKUP("MET LUX ",HELPER!$A:$A,HELPER!$E:$E,0) -> 5.380588 | S4: =IFERROR(R4*HELPER!$AK$2," ") -> 6.2414821 | U4: PL202.1 | V4: PBAT | W4: B12 | X4: RMB12 | Y4: Resin 2A | Z4: {=SUMPRODUCT((BOM!$A$2:$A$391=U4)*(BOM!$F$2:$F$391=Y4)*BOM!$H$2:$H$391*BOM!$G$2:$G$391)/SUMPRODUCT((BOM!$A$2:$A$391=U4)*BOM!$H$2:$H$391*BOM!$G$2:$G$391)} -> 0.138 | AA4: =SUMIF(tblResinWeightedQty12[Film],tblResinWeightedQty12[[#This Row],[Film]],tblResinWeightedQty12[Weighted QTY %]) -> 1
A5: TIPA 302FG | B5: Ext. A (Out - Chillroll) | C5: AO-PBS | D5: =IF(C5="","",IFERROR(_xlfn.XLOOKUP(C5,HELPER!$A$2:$A$81,HELPER!$B$2:$B$81,""),D5)) -> S723 | E5: =IFERROR(_xlfn.XLOOKUP(D5,HELPER!$B:$B,HELPER!$C:$C,""),"") -> RM TA45-08 S723 | F5: =IFERROR(_xlfn.XLOOKUP(D5,HELPER!$B:$B,HELPER!$D:$D,""),"") -> Resin 6 | G5: 8 | H5: 0.015 | I5: =IF(AND(H5<>"",IFERROR(_xlfn.XLOOKUP(D5,HELPER!$B:$B,HELPER!$E:$E,""),"")=""),"Missing price",IFERROR(_xlfn.XLOOKUP(D5,HELPER!$B:$B,HELPER!$E:$E,"")," ")) -> 16.16 | J5: =IFERROR(H5*(IF(G5=8,I5*HELPER!$G$2,BOM!I5*HELPER!$G$3))," ") -> 0.04848 | L5: {=IFERROR(_xlfn.LET(_xlpm.films,Table4[Film],_xlpm.grades,Table4[Grade],_xlpm.pairs,_xlfn._xlws.FILTER(_xlfn.HSTACK(_xlpm.films,_xlpm.grades),(_xlpm.films<>"")*(TRIM(_xlpm.grades)<>"")),_xlpm.uniquePairs,_xlfn.UNIQUE(_xlpm.pairs),_xlpm.sortedPairs,_xlfn._xlws.SORT(_xlpm.uniquePairs,1,1),INDEX(_xlpm.sortedPairs,ROWS($L$2:L5),1)),"")} -> PL202.1 | M5: {=IFERROR(_xlfn.LET(_xlpm.films,Table4[Film],_xlpm.grades,Table4[Grade],_xlpm.pairs,_xlfn._xlws.FILTER(_xlfn.HSTACK(_xlpm.films,_xlpm.grades),(_xlpm.films<>"")*(TRIM(_xlpm.grades)<>"")),_xlpm.uniquePairs,_xlfn.UNIQUE(_xlpm.pairs),_xlpm.sortedPairs,_xlfn._xlws.SORT(_xlpm.uniquePairs,1,1),INDEX(_xlpm.sortedPairs,ROWS($M$2:M5),2)),"")} -> S724 | N5: {=IF(OR(Table2[[#This Row],[Film]]="",Table2[[#This Row],[Grade]]=""),"",IFERROR(INDEX(Table4[Serial Number],MATCH(1,(Table4[Film]=Table2[[#This Row],[Film]])*(Table4[Grade]=Table2[[#This Row],[Grade]]),0)),""))} -> RM TA45-08 S724 | O5: =IF(OR(Table2[[#This Row],[Film]]="",Table2[[#This Row],[Grade]]=""),"",SUMIFS(Table4[Price Calculated(€) Thickness & QTY related],Table4[Film],Table2[[#This Row],[Film]],Table4[Grade],Table2[[#This Row],[Grade]])) -> 0.1764 | Q5: {=IFERROR(INDEX(Table2[Film],MATCH(0,COUNTIF($Q$1:Q4,Table2[Film])+IF(Table2[Film]="",1,0),0)),"")} -> TIPA 302FG | R5: =SUMIF(Table2[Film],"TIPA 312 MFG",Table2[Price Calculated(€) Thickness & QTY related])+_xlfn.XLOOKUP("MET LUX ",HELPER!$A:$A,HELPER!$E:$E,0) -> 5.380588 | S5: =IFERROR(R5*HELPER!$AK$2," ") -> 6.2414821 | U5: PL202.1 | V5: AO-PBS | W5: S723 | X5: RM TA45-08 S723 | Y5: Resin 6 | Z5: {=SUMPRODUCT((BOM!$A$2:$A$391=U5)*(BOM!$F$2:$F$391=Y5)*BOM!$H$2:$H$391*BOM!$G$2:$G$391)/SUMPRODUCT((BOM!$A$2:$A$391=U5)*BOM!$H$2:$H$391*BOM!$G$2:$G$391)} -> 0.02 | AA5: =SUMIF(tblResinWeightedQty12[Film],tblResinWeightedQty12[[#This Row],[Film]],tblResinWeightedQty12[Weighted QTY %]) -> 1
A6: TIPA 302FG | B6: Ext. A (Out - Chillroll) | D6: =IF(C6="","",IFERROR(_xlfn.XLOOKUP(C6,HELPER!$A$2:$A$81,HELPER!$B$2:$B$81,""),D6)) | E6: =IFERROR(_xlfn.XLOOKUP(D6,HELPER!$B:$B,HELPER!$C:$C,""),"") | F6: =IFERROR(_xlfn.XLOOKUP(D6,HELPER!$B:$B,HELPER!$D:$D,""),"") | G6: 8 | I6: =IF(AND(H6<>"",IFERROR(_xlfn.XLOOKUP(D6,HELPER!$B:$B,HELPER!$E:$E,""),"")=""),"Missing price",IFERROR(_xlfn.XLOOKUP(D6,HELPER!$B:$B,HELPER!$E:$E,"")," ")) | J6: =IFERROR(H6*(IF(G6=8,I6*HELPER!$G$2,BOM!I6*HELPER!$G$3))," ") | L6: {=IFERROR(_xlfn.LET(_xlpm.films,Table4[Film],_xlpm.grades,Table4[Grade],_xlpm.pairs,_xlfn._xlws.FILTER(_xlfn.HSTACK(_xlpm.films,_xlpm.grades),(_xlpm.films<>"")*(TRIM(_xlpm.grades)<>"")),_xlpm.uniquePairs,_xlfn.UNIQUE(_xlpm.pairs),_xlpm.sortedPairs,_xlfn._xlws.SORT(_xlpm.uniquePairs,1,1),INDEX(_xlpm.sortedPairs,ROWS($L$2:L6),1)),"")} -> PL202.1 | M6: {=IFERROR(_xlfn.LET(_xlpm.films,Table4[Film],_xlpm.grades,Table4[Grade],_xlpm.pairs,_xlfn._xlws.FILTER(_xlfn.HSTACK(_xlpm.films,_xlpm.grades),(_xlpm.films<>"")*(TRIM(_xlpm.grades)<>"")),_xlpm.uniquePairs,_xlfn.UNIQUE(_xlpm.pairs),_xlpm.sortedPairs,_xlfn._xlws.SORT(_xlpm.uniquePairs,1,1),INDEX(_xlpm.sortedPairs,ROWS($M$2:M6),2)),"")} -> KAB59A | N6: {=IF(OR(Table2[[#This Row],[Film]]="",Table2[[#This Row],[Grade]]=""),"",IFERROR(INDEX(Table4[Serial Number],MATCH(1,(Table4[Film]=Table2[[#This Row],[Film]])*(Table4[Grade]=Table2[[#This Row],[Grade]]),0)),""))} -> RM A KAB59A | O6: =IF(OR(Table2[[#This Row],[Film]]="",Table2[[#This Row],[Grade]]=""),"",SUMIFS(Table4[Price Calculated(€) Thickness & QTY related],Table4[Film],Table2[[#This Row],[Film]],Table4[Grade],Table2[[#This Row],[Grade]])) -> 0.06795 | Q6: {=IFERROR(INDEX(Table2[Film],MATCH(0,COUNTIF($Q$1:Q5,Table2[Film])+IF(Table2[Film]="",1,0),0)),"")} -> TIPA 302FG W | R6: =SUMIF(Table2[Film],"TIPA 312 MFG",Table2[Price Calculated(€) Thickness & QTY related])+_xlfn.XLOOKUP("MET LUX ",HELPER!$A:$A,HELPER!$E:$E,0) -> 5.380588 | S6: =IFERROR(R6*HELPER!$AK$2," ") -> 6.2414821 | U6: PL202.1 | V6: SLAB-PBSA | W6: S724 | X6: RM TA45-08 S724 | Y6: Resin 7 | Z6: {=SUMPRODUCT((BOM!$A$2:$A$391=U6)*(BOM!$F$2:$F$391=Y6)*BOM!$H$2:$H$391*BOM!$G$2:$G$391)/SUMPRODUCT((BOM!$A$2:$A$391=U6)*BOM!$H$2:$H$391*BOM!$G$2:$G$391)} -> 0.012 | AA6: =SUMIF(tblResinWeightedQty12[Film],tblResinWeightedQty12[[#This Row],[Film]],tblResinWeightedQty12[Weighted QTY %]) -> 1
A7: TIPA 302FG | B7: Ext. A (Out - Chillroll) | D7: =IF(C7="","",IFERROR(_xlfn.XLOOKUP(C7,HELPER!$A$2:$A$81,HELPER!$B$2:$B$81,""),D7)) | E7: =IFERROR(_xlfn.XLOOKUP(D7,HELPER!$B:$B,HELPER!$C:$C,""),"") | F7: =IFERROR(_xlfn.XLOOKUP(D7,HELPER!$B:$B,HELPER!$D:$D,""),"") | G7: 8 | I7: =IF(AND(H7<>"",IFERROR(_xlfn.XLOOKUP(D7,HELPER!$B:$B,HELPER!$E:$E,""),"")=""),"Missing price",IFERROR(_xlfn.XLOOKUP(D7,HELPER!$B:$B,HELPER!$E:$E,"")," ")) | J7: =IFERROR(H7*(IF(G7=8,I7*HELPER!$G$2,BOM!I7*HELPER!$G$3))," ") | L7: {=IFERROR(_xlfn.LET(_xlpm.films,Table4[Film],_xlpm.grades,Table4[Grade],_xlpm.pairs,_xlfn._xlws.FILTER(_xlfn.HSTACK(_xlpm.films,_xlpm.grades),(_xlpm.films<>"")*(TRIM(_xlpm.grades)<>"")),_xlpm.uniquePairs,_xlfn.UNIQUE(_xlpm.pairs),_xlpm.sortedPairs,_xlfn._xlws.SORT(_xlpm.uniquePairs,1,1),INDEX(_xlpm.sortedPairs,ROWS($L$2:L7),1)),"")} -> PL202.1 | M7: {=IFERROR(_xlfn.LET(_xlpm.films,Table4[Film],_xlpm.grades,Table4[Grade],_xlpm.pairs,_xlfn._xlws.FILTER(_xlfn.HSTACK(_xlpm.films,_xlpm.grades),(_xlpm.films<>"")*(TRIM(_xlpm.grades)<>"")),_xlpm.uniquePairs,_xlfn.UNIQUE(_xlpm.pairs),_xlpm.sortedPairs,_xlfn._xlws.SORT(_xlpm.uniquePairs,1,1),INDEX(_xlpm.sortedPairs,ROWS($M$2:M7),2)),"")} -> BVE8049P | N7: {=IF(OR(Table2[[#This Row],[Film]]="",Table2[[#This Row],[Grade]]=""),"",IFERROR(INDEX(Table4[Serial Number],MATCH(1,(Table4[Film]=Table2[[#This Row],[Film]])*(Table4[Grade]=Table2[[#This Row],[Grade]]),0)),""))} -> BVE8049P | O7: =IF(OR(Table2[[#This Row],[Film]]="",Table2[[#This Row],[Grade]]=""),"",SUMIFS(Table4[Price Calculated(€) Thickness & QTY related],Table4[Film],Table2[[#This Row],[Film]],Table4[Grade],Table2[[#This Row],[Grade]])) -> 4.699 | Q7: {=IFERROR(INDEX(Table2[Film],MATCH(0,COUNTIF($Q$1:Q6,Table2[Film])+IF(Table2[Film]="",1,0),0)),"")} -> TIPA 306M | R7: =SUMIF(Table2[Film],"TIPA 312 MFG",Table2[Price Calculated(€) Thickness & QTY related])+_xlfn.XLOOKUP("MET LUX ",HELPER!$A:$A,HELPER!$E:$E,0) -> 5.380588 | S7: =IFERROR(R7*HELPER!$AK$2," ") -> 6.2414821 | U7: PL202.1 | V7: AB-PLA | W7: KAB59A | X7: RM A KAB59A | Y7: Resin 8 | Z7: {=SUMPRODUCT((BOM!$A$2:$A$391=U7)*(BOM!$F$2:$F$391=Y7)*BOM!$H$2:$H$391*BOM!$G$2:$G$391)/SUMPRODUCT((BOM!$A$2:$A$391=U7)*BOM!$H$2:$H$391*BOM!$G$2:$G$391)} -> 0.009 | AA7: =SUMIF(tblResinWeightedQty12[Film],tblResinWeightedQty12[[#This Row],[Film]],tblResinWeightedQty12[Weighted QTY %]) -> 1
A8: TIPA 302FG | B8: Ext. A (Out - Chillroll) | D8: =IF(C8="","",IFERROR(_xlfn.XLOOKUP(C8,HELPER!$A$2:$A$81,HELPER!$B$2:$B$81,""),D8)) | E8: =IFERROR(_xlfn.XLOOKUP(D8,HELPER!$B:$B,HELPER!$C:$C,""),"") | F8: =IFERROR(_xlfn.XLOOKUP(D8,HELPER!$B:$B,HELPER!$D:$D,""),"") | G8: 8 | I8: =IF(AND(H8<>"",IFERROR(_xlfn.XLOOKUP(D8,HELPER!$B:$B,HELPER!$E:$E,""),"")=""),"Missing price",IFERROR(_xlfn.XLOOKUP(D8,HELPER!$B:$B,HELPER!$E:$E,"")," ")) | J8: =IFERROR(H8*(IF(G8=8,I8*HELPER!$G$2,BOM!I8*HELPER!$G$3))," ") | L8: {=IFERROR(_xlfn.LET(_xlpm.films,Table4[Film],_xlpm.grades,Table4[Grade],_xlpm.pairs,_xlfn._xlws.FILTER(_xlfn.HSTACK(_xlpm.films,_xlpm.grades),(_xlpm.films<>"")*(TRIM(_xlpm.grades)<>"")),_xlpm.uniquePairs,_xlfn.UNIQUE(_xlpm.pairs),_xlpm.sortedPairs,_xlfn._xlws.SORT(_xlpm.uniquePairs,1,1),INDEX(_xlpm.sortedPairs,ROWS($L$2:L8),1)),"")} -> PL202.1 | M8: {=IFERROR(_xlfn.LET(_xlpm.films,Table4[Film],_xlpm.grades,Table4[Grade],_xlpm.pairs,_xlfn._xlws.FILTER(_xlfn.HSTACK(_xlpm.films,_xlpm.grades),(_xlpm.films<>"")*(TRIM(_xlpm.grades)<>"")),_xlpm.uniquePairs,_xlfn.UNIQUE(_xlpm.pairs),_xlpm.sortedPairs,_xlfn._xlws.SORT(_xlpm.uniquePairs,1,1),INDEX(_xlpm.sortedPairs,ROWS($M$2:M8),2)),"")} -> B12 | N8: {=IF(OR(Table2[[#This Row],[Film]]="",Table2[[#This Row],[Grade]]=""),"",IFERROR(INDEX(Table4[Serial Number],MATCH(1,(Table4[Film]=Table2[[#This Row],[Film]])*(Table4[Grade]=Table2[[#This Row],[Grade]]),0)),""))} -> RMB12 | O8: =IF(OR(Table2[[#This Row],[Film]]="",Table2[[#This Row],[Grade]]=""),"",SUMIFS(Table4[Price Calculated(€) Thickness & QTY related],Table4[Film],Table2[[#This Row],[Film]],Table4[Grade],Table2[[#This Row],[Grade]])) -> 0.24978 | Q8: {=IFERROR(INDEX(Table2[Film],MATCH(0,COUNTIF($Q$1:Q7,Table2[Film])+IF(Table2[Film]="",1,0),0)),"")} -> TIPA 306W | R8: =SUMIF(Table2[Film],"TIPA 312 MFG",Table2[Price Calculated(€) Thickness & QTY related])+_xlfn.XLOOKUP("MET LUX ",HELPER!$A:$A,HELPER!$E:$E,0) -> 5.380588 | S8: =IFERROR(R8*HELPER!$AK$2," ") -> 6.2414821 | U8: PL202.1 | V8: PBSA | W8: FD92PM | X8: RMPM2 | Y8: Resin 9C | Z8: {=SUMPRODUCT((BOM!$A$2:$A$391=U8)*(BOM!$F$2:$F$391=Y8)*BOM!$H$2:$H$391*BOM!$G$2:$G$391)/SUMPRODUCT((BOM!$A$2:$A$391=U8)*BOM!$H$2:$H$391*BOM!$G$2:$G$391)} -> 0.4818 | AA8: =SUMIF(tblResinWeightedQty12[Film],tblResinWeightedQty12[[#This Row],[Film]],tblResinWeightedQty12[Weighted QTY %]) -> 1
A9: TIPA 302FG | B9: Ext. A (Out - Chillroll) | D9: =IF(C9="","",IFERROR(_xlfn.XLOOKUP(C9,HELPER!$A$2:$A$81,HELPER!$B$2:$B$81,""),D9)) | E9: =IFERROR(_xlfn.XLOOKUP(D9,HELPER!$B:$B,HELPER!$C:$C,""),"") | F9: =IFERROR(_xlfn.XLOOKUP(D9,HELPER!$B:$B,HELPER!$D:$D,""),"") | G9: 8 | I9: =IF(AND(H9<>"",IFERROR(_xlfn.XLOOKUP(D9,HELPER!$B:$B,HELPER!$E:$E,""),"")=""),"Missing price",IFERROR(_xlfn.XLOOKUP(D9,HELPER!$B:$B,HELPER!$E:$E,"")," ")) | J9: =IFERROR(H9*(IF(G9=8,I9*HELPER!$G$2,BOM!I9*HELPER!$G$3))," ") | L9: {=IFERROR(_xlfn.LET(_xlpm.films,Table4[Film],_xlpm.grades,Table4[Grade],_xlpm.pairs,_xlfn._xlws.FILTER(_xlfn.HSTACK(_xlpm.films,_xlpm.grades),(_xlpm.films<>"")*(TRIM(_xlpm.grades)<>"")),_xlpm.uniquePairs,_xlfn.UNIQUE(_xlpm.pairs),_xlpm.sortedPairs,_xlfn._xlws.SORT(_xlpm.uniquePairs,1,1),INDEX(_xlpm.sortedPairs,ROWS($L$2:L9),1)),"")} -> PL202.2 | M9: {=IFERROR(_xlfn.LET(_xlpm.films,Table4[Film],_xlpm.grades,Table4[Grade],_xlpm.pairs,_xlfn._xlws.FILTER(_xlfn.HSTACK(_xlpm.films,_xlpm.grades),(_xlpm.films<>"")*(TRIM(_xlpm.grades)<>"")),_xlpm.uniquePairs,_xlfn.UNIQUE(_xlpm.pairs),_xlpm.sortedPairs,_xlfn._xlws.SORT(_xlpm.uniquePairs,1,1),INDEX(_xlpm.sortedPairs,ROWS($M$2:M9),2)),"")} -> LX175 | N9: {=IF(OR(Table2[[#This Row],[Film]]="",Table2[[#This Row],[Grade]]=""),"",IFERROR(INDEX(Table4[Serial Number],MATCH(1,(Table4[Film]=Table2[[#This Row],[Film]])*(Table4[Grade]=Table2[[#This Row],[Grade]]),0)),""))} -> RMLX175 | O9: =IF(OR(Table2[[#This Row],[Film]]="",Table2[[#This Row],[Grade]]=""),"",SUMIFS(Table4[Price Calculated(€) Thickness & QTY related],Table4[Film],Table2[[#This Row],[Film]],Table4[Grade],Table2[[#This Row],[Grade]])) -> 1.50258 | Q9: {=IFERROR(INDEX(Table2[Film],MATCH(0,COUNTIF($Q$1:Q8,Table2[Film])+IF(Table2[Film]="",1,0),0)),"")} -> TIPA 312 MFG | R9: =SUMIF(Table2[Film],"TIPA 312 MFG",Table2[Price Calculated(€) Thickness & QTY related])+_xlfn.XLOOKUP("MET LUX ",HELPER!$A:$A,HELPER!$E:$E,0) -> 5.380588 | S9: =IFERROR(R9*HELPER!$AK$2," ") -> 6.2414821 | U9: PL202.2 | V9: PVOH | W9: BVE8049P | X9: BVE8049P | Y9: BVE8049P | Z9: {=SUMPRODUCT((BOM!$A$2:$A$391=U9)*(BOM!$F$2:$F$391=Y9)*BOM!$H$2:$H$391*BOM!$G$2:$G$391)/SUMPRODUCT((BOM!$A$2:$A$391=U9)*BOM!$H$2:$H$391*BOM!$G$2:$G$391)} -> 0.254 | AA9: =SUMIF(tblResinWeightedQty12[Film],tblResinWeightedQty12[[#This Row],[Film]],tblResinWeightedQty12[Weighted QTY %]) -> 1
A10: TIPA 302FG | B10: Ext. A (Out - Chillroll) | D10: =IF(C10="","",IFERROR(_xlfn.XLOOKUP(C10,HELPER!$A$2:$A$81,HELPER!$B$2:$B$81,""),D10)) | E10: =IFERROR(_xlfn.XLOOKUP(D10,HELPER!$B:$B,HELPER!$C:$C,""),"") | F10: =IFERROR(_xlfn.XLOOKUP(D10,HELPER!$B:$B,HELPER!$D:$D,""),"") | G10: 8 | I10: =IF(AND(H10<>"",IFERROR(_xlfn.XLOOKUP(D10,HELPER!$B:$B,HELPER!$E:$E,""),"")=""),"Missing price",IFERROR(_xlfn.XLOOKUP(D10,HELPER!$B:$B,HELPER!$E:$E,"")," ")) | J10: =IFERROR(H10*(IF(G10=8,I10*HELPER!$G$2,BOM!I10*HELPER!$G$3))," ") | L10: {=IFERROR(_xlfn.LET(_xlpm.films,Table4[Film],_xlpm.grades,Table4[Grade],_xlpm.pairs,_xlfn._xlws.FILTER(_xlfn.HSTACK(_xlpm.films,_xlpm.grades),(_xlpm.films<>"")*(TRIM(_xlpm.grades)<>"")),_xlpm.uniquePairs,_xlfn.UNIQUE(_xlpm.pairs),_xlpm.sortedPairs,_xlfn._xlws.SORT(_xlpm.uniquePairs,1,1),INDEX(_xlpm.sortedPairs,ROWS($L$2:L10),1)),"")} -> PL202.2 | M10: {=IFERROR(_xlfn.LET(_xlpm.films,Table4[Film],_xlpm.grades,Table4[Grade],_xlpm.pairs,_xlfn._xlws.FILTER(_xlfn.HSTACK(_xlpm.films,_xlpm.grades),(_xlpm.films<>"")*(TRIM(_xlpm.grades)<>"")),_xlpm.uniquePairs,_xlfn.UNIQUE(_xlpm.pairs),_xlpm.sortedPairs,_xlfn._xlws.SORT(_xlpm.uniquePairs,1,1),INDEX(_xlpm.sortedPairs,ROWS($M$2:M10),2)),"")} -> P65D | N10: {=IF(OR(Table2[[#This Row],[Film]]="",Table2[[#This Row],[Grade]]=""),"",IFERROR(INDEX(Table4[Serial Number],MATCH(1,(Table4[Film]=Table2[[#This Row],[Film]])*(Table4[Grade]=Table2[[#This Row],[Grade]]),0)),""))} -> RMP65D | O10: =IF(OR(Table2[[#This Row],[Film]]="",Table2[[#This Row],[Grade]]=""),"",SUMIFS(Table4[Price Calculated(€) Thickness & QTY related],Table4[Film],Table2[[#This Row],[Film]],Table4[Grade],Table2[[#This Row],[Grade]])) -> 0.8322 | Q10: {=IFERROR(INDEX(Table2[Film],MATCH(0,COUNTIF($Q$1:Q9,Table2[Film])+IF(Table2[Film]="",1,0),0)),"")} -> TIPA 312MFGW | R10: =SUMIF(Table2[Film],"TIPA 312 MFG",Table2[Price Calculated(€) Thickness & QTY related])+_xlfn.XLOOKUP("MET LUX ",HELPER!$A:$A,HELPER!$E:$E,0) -> 5.380588 | S10: =IFERROR(R10*HELPER!$AK$2," ") -> 6.2414821 | U10: PL202.2 | V10: PLA | W10: LX175 | X10: RMLX175 | Y10: Resin 1A | Z10: {=SUMPRODUCT((BOM!$A$2:$A$391=U10)*(BOM!$F$2:$F$391=Y10)*BOM!$H$2:$H$391*BOM!$G$2:$G$391)/SUMPRODUCT((BOM!$A$2:$A$391=U10)*BOM!$H$2:$H$391*BOM!$G$2:$G$391)} -> 0.474 | AA10: =SUMIF(tblResinWeightedQty12[Film],tblResinWeightedQty12[[#This Row],[Film]],tblResinWeightedQty12[Weighted QTY %]) -> 1
A11: TIPA 302FG | B11: Ext. A (Out - Chillroll) | D11: =IF(C11="","",IFERROR(_xlfn.XLOOKUP(C11,HELPER!$A$2:$A$81,HELPER!$B$2:$B$81,""),D11)) | E11: =IFERROR(_xlfn.XLOOKUP(D11,HELPER!$B:$B,HELPER!$C:$C,""),"") | F11: =IFERROR(_xlfn.XLOOKUP(D11,HELPER!$B:$B,HELPER!$D:$D,""),"") | G11: 8 | I11: =IF(AND(H11<>"",IFERROR(_xlfn.XLOOKUP(D11,HELPER!$B:$B,HELPER!$E:$E,""),"")=""),"Missing price",IFERROR(_xlfn.XLOOKUP(D11,HELPER!$B:$B,HELPER!$E:$E,"")," ")) | J11: =IFERROR(H11*(IF(G11=8,I11*HELPER!$G$2,BOM!I11*HELPER!$G$3))," ") | L11: {=IFERROR(_xlfn.LET(_xlpm.films,Table4[Film],_xlpm.grades,Table4[Grade],_xlpm.pairs,_xlfn._xlws.FILTER(_xlfn.HSTACK(_xlpm.films,_xlpm.grades),(_xlpm.films<>"")*(TRIM(_xlpm.grades)<>"")),_xlpm.uniquePairs,_xlfn.UNIQUE(_xlpm.pairs),_xlpm.sortedPairs,_xlfn._xlws.SORT(_xlpm.uniquePairs,1,1),INDEX(_xlpm.sortedPairs,ROWS($L$2:L11),1)),"")} -> PL202.2 | M11: {=IFERROR(_xlfn.LET(_xlpm.films,Table4[Film],_xlpm.grades,Table4[Grade],_xlpm.pairs,_xlfn._xlws.FILTER(_xlfn.HSTACK(_xlpm.films,_xlpm.grades),(_xlpm.films<>"")*(TRIM(_xlpm.grades)<>"")),_xlpm.uniquePairs,_xlfn.UNIQUE(_xlpm.pairs),_xlpm.sortedPairs,_xlfn._xlws.SORT(_xlpm.uniquePairs,1,1),INDEX(_xlpm.sortedPairs,ROWS($M$2:M11),2)),"")} -> S723 | N11: {=IF(OR(Table2[[#This Row],[Film]]="",Table2[[#This Row],[Grade]]=""),"",IFERROR(INDEX(Table4[Serial Number],MATCH(1,(Table4[Film]=Table2[[#This Row],[Film]])*(Table4[Grade]=Table2[[#This Row],[Grade]]),0)),""))} -> RM TA45-08 S723 | O11: =IF(OR(Table2[[#This Row],[Film]]="",Table2[[#This Row],[Grade]]=""),"",SUMIFS(Table4[Price Calculated(€) Thickness & QTY related],Table4[Film],Table2[[#This Row],[Film]],Table4[Grade],Table2[[#This Row],[Grade]])) -> 0.3232 | Q11: TIPA 312 MET | R11: =SUMIF(Table2[Film],"TIPA 312 MFG",Table2[Price Calculated(€) Thickness & QTY related])+_xlfn.XLOOKUP("MET LUX ",HELPER!$A:$A,HELPER!$E:$E,0) -> 5.380588 | S11: =IFERROR(R11*HELPER!$AK$2," ") -> 6.2414821 | U11: PL202.2 | V11: PBAT | W11: B12 | X11: RMB12 | Y11: Resin 2A | Z11: {=SUMPRODUCT((BOM!$A$2:$A$391=U11)*(BOM!$F$2:$F$391=Y11)*BOM!$H$2:$H$391*BOM!$G$2:$G$391)/SUMPRODUCT((BOM!$A$2:$A$391=U11)*BOM!$H$2:$H$391*BOM!$G$2:$G$391)} -> 0.138 | AA11: =SUMIF(tblResinWeightedQty12[Film],tblResinWeightedQty12[[#This Row],[Film]],tblResinWeightedQty12[Weighted QTY %]) -> 1
A12: TIPA 302FG | B12: Ext. B | D12: =IF(C12="","",IFERROR(_xlfn.XLOOKUP(C12,HELPER!$A$2:$A$81,HELPER!$B$2:$B$81,""),D12)) | E12: =IFERROR(_xlfn.XLOOKUP(D12,HELPER!$B:$B,HELPER!$C:$C,""),"") | F12: =IFERROR(_xlfn.XLOOKUP(D12,HELPER!$B:$B,HELPER!$D:$D,""),"") | G12: 8 | I12: =IF(AND(H12<>"",IFERROR(_xlfn.XLOOKUP(D12,HELPER!$B:$B,HELPER!$E:$E,""),"")=""),"Missing price",IFERROR(_xlfn.XLOOKUP(D12,HELPER!$B:$B,HELPER!$E:$E,"")," ")) | J12: =IFERROR(H12*(IF(G12=8,I12*HELPER!$G$2,BOM!I12*HELPER!$G$3))," ") | L12: {=IFERROR(_xlfn.LET(_xlpm.films,Table4[Film],_xlpm.grades,Table4[Grade],_xlpm.pairs,_xlfn._xlws.FILTER(_xlfn.HSTACK(_xlpm.films,_xlpm.grades),(_xlpm.films<>"")*(TRIM(_xlpm.grades)<>"")),_xlpm.uniquePairs,_xlfn.UNIQUE(_xlpm.pairs),_xlpm.sortedPairs,_xlfn._xlws.SORT(_xlpm.uniquePairs,1,1),INDEX(_xlpm.sortedPairs,ROWS($L$2:L12),1)),"")} -> PL202.2 | M12: {=IFERROR(_xlfn.LET(_xlpm.films,Table4[Film],_xlpm.grades,Table4[Grade],_xlpm.pairs,_xlfn._xlws.FILTER(_xlfn.HSTACK(_xlpm.films,_xlpm.grades),(_xlpm.films<>"")*(TRIM(_xlpm.grades)<>"")),_xlpm.uniquePairs,_xlfn.UNIQUE(_xlpm.pairs),_xlpm.sortedPairs,_xlfn._xlws.SORT(_xlpm.uniquePairs,1,1),INDEX(_xlpm.sortedPairs,ROWS($M$2:M12),2)),"")} -> BVE8049P | N12: {=IF(OR(Table2[[#This Row],[Film]]="",Table2[[#This Row],[Grade]]=""),"",IFERROR(INDEX(Table4[Serial Number],MATCH(1,(Table4[Film]=Table2[[#This Row],[Film]])*(Table4[Grade]=Table2[[#This Row],[Grade]]),0)),""))} -> BVE8049P | O12: =IF(OR(Table2[[#This Row],[Film]]="",Table2[[#This Row],[Grade]]=""),"",SUMIFS(Table4[Price Calculated(€) Thickness & QTY related],Table4[Film],Table2[[#This Row],[Film]],Table4[Grade],Table2[[#This Row],[Grade]])) -> 4.699 | Q12: {=IFERROR(INDEX(Table2[Film],MATCH(0,COUNTIF($Q$1:Q11,Table2[Film])+IF(Table2[Film]="",1,0),0)),"")} | R12: =SUMIF(Table2[Film],"TIPA 312 MFG",Table2[Price Calculated(€) Thickness & QTY related])+_xlfn.XLOOKUP("MET LUX ",HELPER!$A:$A,HELPER!$E:$E,0) -> 5.380588 | S12: =IFERROR(R12*HELPER!$AK$2," ") -> 6.2414821 | U12: PL202.2 | V12: PCL | W12: P65D | X12: RMP65D | Y12: Resin 4A | Z12: {=SUMPRODUCT((BOM!$A$2:$A$391=U12)*(BOM!$F$2:$F$391=Y12)*BOM!$H$2:$H$391*BOM!$G$2:$G$391)/SUMPRODUCT((BOM!$A$2:$A$391=U12)*BOM!$H$2:$H$391*BOM!$G$2:$G$391)} -> 0.114 | AA12: =SUMIF(tblResinWeightedQty12[Film],tblResinWeightedQty12[[#This Row],[Film]],tblResinWeightedQty12[Weighted QTY %]) -> 1
A13: TIPA 302FG | B13: Ext. B | D13: =IF(C13="","",IFERROR(_xlfn.XLOOKUP(C13,HELPER!$A$2:$A$81,HELPER!$B$2:$B$81,""),D13)) | E13: =IFERROR(_xlfn.XLOOKUP(D13,HELPER!$B:$B,HELPER!$C:$C,""),"") | F13: =IFERROR(_xlfn.XLOOKUP(D13,HELPER!$B:$B,HELPER!$D:$D,""),"") | G13: 24 | I13: =IF(AND(H13<>"",IFERROR(_xlfn.XLOOKUP(D13,HELPER!$B:$B,HELPER!$E:$E,""),"")=""),"Missing price",IFERROR(_xlfn.XLOOKUP(D13,HELPER!$B:$B,HELPER!$E:$E,"")," ")) | J13: =IFERROR(H13*(IF(G13=8,I13*HELPER!$G$2,BOM!I13*HELPER!$G$3))," ") | L13: {=IFERROR(_xlfn.LET(_xlpm.films,Table4[Film],_xlpm.grades,Table4[Grade],_xlpm.pairs,_xlfn._xlws.FILTER(_xlfn.HSTACK(_xlpm.films,_xlpm.grades),(_xlpm.films<>"")*(TRIM(_xlpm.grades)<>"")),_xlpm.uniquePairs,_xlfn.UNIQUE(_xlpm.pairs),_xlpm.sortedPairs,_xlfn._xlws.SORT(_xlpm.uniquePairs,1,1),INDEX(_xlpm.sortedPairs,ROWS($L$2:L13),1)),"")} -> PL202.2 | M13: {=IFERROR(_xlfn.LET(_xlpm.films,Table4[Film],_xlpm.grades,Table4[Grade],_xlpm.pairs,_xlfn._xlws.FILTER(_xlfn.HSTACK(_xlpm.films,_xlpm.grades),(_xlpm.films<>"")*(TRIM(_xlpm.grades)<>"")),_xlpm.uniquePairs,_xlfn.UNIQUE(_xlpm.pairs),_xlpm.sortedPairs,_xlfn._xlws.SORT(_xlpm.uniquePairs,1,1),INDEX(_xlpm.sortedPairs,ROWS($M$2:M13),2)),"")} -> B12 | N13: {=IF(OR(Table2[[#This Row],[Film]]="",Table2[[#This Row],[Grade]]=""),"",IFERROR(INDEX(Table4[Serial Number],MATCH(1,(Table4[Film]=Table2[[#This Row],[Film]])*(Table4[Grade]=Table2[[#This Row],[Grade]]),0)),""))} -> RMB12 | O13: =IF(OR(Table2[[#This Row],[Film]]="",Table2[[#This Row],[Grade]]=""),"",SUMIFS(Table4[Price Calculated(€) Thickness & QTY related],Table4[Film],Table2[[#This Row],[Film]],Table4[Grade],Table2[[#This Row],[Grade]])) -> 0.24978 | Q13: {=IFERROR(INDEX(Table2[Film],MATCH(0,COUNTIF($Q$1:Q12,Table2[Film])+IF(Table2[Film]="",1,0),0)),"")} | R13: =SUMIF(Table2[Film],"TIPA 312 MFG",Table2[Price Calculated(€) Thickness & QTY related])+_xlfn.XLOOKUP("MET LUX ",HELPER!$A:$A,HELPER!$E:$E,0) -> 5.380588 | S13: =IFERROR(R13*HELPER!$AK$2," ") -> 6.2414821 | U13: PL202.2 | V13: AO-PBS | W13: S723 | X13: RM TA45-08 S723 | Y13: Resin 6 | Z13: {=SUMPRODUCT((BOM!$A$2:$A$391=U13)*(BOM!$F$2:$F$391=Y13)*BOM!$H$2:$H$391*BOM!$G$2:$G$391)/SUMPRODUCT((BOM!$A$2:$A$391=U13)*BOM!$H$2:$H$391*BOM!$G$2:$G$391)} -> 0.02 | AA13: =SUMIF(tblResinWeightedQty12[Film],tblResinWeightedQty12[[#This Row],[Film]],tblResinWeightedQty12[Weighted QTY %]) -> 1
A14: TIPA 302FG | B14: Ext. B | D14: =IF(C14="","",IFERROR(_xlfn.XLOOKUP(C14,HELPER!$A$2:$A$81,HELPER!$B$2:$B$81,""),D14)) | E14: =IFERROR(_xlfn.XLOOKUP(D14,HELPER!$B:$B,HELPER!$C:$C,""),"") | F14: =IFERROR(_xlfn.XLOOKUP(D14,HELPER!$B:$B,HELPER!$D:$D,""),"") | G14: 24 | I14: =IF(AND(H14<>"",IFERROR(_xlfn.XLOOKUP(D14,HELPER!$B:$B,HELPER!$E:$E,""),"")=""),"Missing price",IFERROR(_xlfn.XLOOKUP(D14,HELPER!$B:$B,HELPER!$E:$E,"")," ")) | J14: =IFERROR(H14*(IF(G14=8,I14*HELPER!$G$2,BOM!I14*HELPER!$G$3))," ") | L14: {=IFERROR(_xlfn.LET(_xlpm.films,Table4[Film],_xlpm.grades,Table4[Grade],_xlpm.pairs,_xlfn._xlws.FILTER(_xlfn.HSTACK(_xlpm.films,_xlpm.grades),(_xlpm.films<>"")*(TRIM(_xlpm.grades)<>"")),_xlpm.uniquePairs,_xlfn.UNIQUE(_xlpm.pairs),_xlpm.sortedPairs,_xlfn._xlws.SORT(_xlpm.uniquePairs,1,1),INDEX(_xlpm.sortedPairs,ROWS($L$2:L14),1)),"")} -> PL202.3 | M14: {=IFERROR(_xlfn.LET(_xlpm.films,Table4[Film],_xlpm.grades,Table4[Grade],_xlpm.pairs,_xlfn._xlws.FILTER(_xlfn.HSTACK(_xlpm.films,_xlpm.grades),(_xlpm.films<>"")*(TRIM(_xlpm.grades)<>"")),_xlpm.uniquePairs,_xlfn.UNIQUE(_xlpm.pairs),_xlpm.sortedPairs,_xlfn._xlws.SORT(_xlpm.uniquePairs,1,1),INDEX(_xlpm.sortedPairs,ROWS($M$2:M14),2)),"")} -> LX175 | N14: {=IF(OR(Table2[[#This Row],[Film]]="",Table2[[#This Row],[Grade]]=""),"",IFERROR(INDEX(Table4[Serial Number],MATCH(1,(Table4[Film]=Table2[[#This Row],[Film]])*(Table4[Grade]=Table2[[#This Row],[Grade]]),0)),""))} -> RMLX175 | O14: =IF(OR(Table2[[#This Row],[Film]]="",Table2[[#This Row],[Grade]]=""),"",SUMIFS(Table4[Price Calculated(€) Thickness & QTY related],Table4[Film],Table2[[#This Row],[Film]],Table4[Grade],Table2[[#This Row],[Grade]])) -> 1.50258 | Q14: {=IFERROR(INDEX(Table2[Film],MATCH(0,COUNTIF($Q$1:Q13,Table2[Film])+IF(Table2[Film]="",1,0),0)),"")} | R14: =SUMIF(Table2[Film],"TIPA 312 MFG",Table2[Price Calculated(€) Thickness & QTY related])+_xlfn.XLOOKUP("MET LUX ",HELPER!$A:$A,HELPER!$E:$E,0) -> 5.380588 | S14: =IFERROR(R14*HELPER!$AK$2," ") -> 6.2414821 | U14: PL202.3 | V14: PVOH | W14: BVE8049P | X14: BVE8049P | Y14: BVE8049P | Z14: {=SUMPRODUCT((BOM!$A$2:$A$391=U14)*(BOM!$F$2:$F$391=Y14)*BOM!$H$2:$H$391*BOM!$G$2:$G$391)/SUMPRODUCT((BOM!$A$2:$A$391=U14)*BOM!$H$2:$H$391*BOM!$G$2:$G$391)} -> 0.196 | AA14: =SUMIF(tblResinWeightedQty12[Film],tblResinWeightedQty12[[#This Row],[Film]],tblResinWeightedQty12[Weighted QTY %]) -> 1
